<?xml version="1.0" ?>
<!-- =================================================================================== -->
<!-- |    This document was autogenerated by xacro from /home/zhouqiangong/agx_arm_ws/src/nero-dual-arm/src/agx_arm_urdf/nero/urdf/nero_dual_arm_description.xacro | -->
<!-- |    EDITING THIS FILE BY HAND IS NOT RECOMMENDED                                 | -->
<!-- =================================================================================== -->
<!--
  中文说明：
  - 本文件是 Nero “双臂”顶层装配模型（xacro）。
  - 目标：在一个统一的全局坐标系下同时包含左臂与右臂，并在模型层面固定它们的相对安装位姿。
  - 坐标系约定：
    - `world`：根坐标系
    - `body`：身体/肩膀中点坐标系（你要求的“左右两臂肩膀中间”为原点）。当前 `world_to_body` 为单位变换。
  - 装配关系：
    - 通过复用 `nero_arm_macro.xacro` 中的 `nero_arm` 宏分别实例化 `left_` 与 `right_` 两套机械臂。
    - 左右肩在 `body` 坐标系下沿 y 轴对称放置，间距 0.5m：`y=+0.25` 与 `y=-0.25`。
    - 右臂相对左臂“背对背”：在相同 roll/pitch 下，右臂 yaw = 左臂 yaw + 派（见下方两个 origin 块）。

  如何在 RViz / robot_state_publisher 加载（ROS2 常见用法）：
  - 思路：xacro 需要先展开成 URDF 字符串，再作为参数 robot_description 交给 robot_state_publisher。
  - 方式一（命令行临时验证，推荐先跑通）：
    - 先 source ROS2 环境与工作区，然后执行类似（xacro 使用 inorder 选项）：
      - ros2 run xacro xacro -o /tmp/nero_dual.urdf &lt;path&gt;/nero_dual_arm_description.xacro
      - ros2 run robot_state_publisher robot_state_publisher -p robot_description:="$(cat /tmp/nero_dual.urdf)"
      - 再开 RViz，添加 RobotModel，并确保订阅 /robot_description
  - 方式二（在 launch 里加载，工程化用法）：
    - 在 launch 里用 xacro 生成 robot_description，再传给 robot_state_publisher 节点参数。
    - 若已有 display/rviz 启动文件，可把 URDF 源替换成本 xacro。
-->
<robot name="nero_dual_arm">
  <!-- 全局装配坐标系：原点为两侧肩膀基座中点 -->
  <link name="world"/>
  <link name="body"/>
  <joint name="world_to_body" type="fixed">
    <parent link="world"/>
    <child link="body"/>
    <origin rpy="0 0 0" xyz="0 0 0"/>
  </joint>
  <!-- 将单臂基座挂载到父 link（装配入口） -->
  <joint name="left_mount_joint" type="fixed">
    <parent link="body"/>
    <child link="left_base_link"/>
    <origin rpy="0 -1.5707926 -1.5707926" xyz="0 0.20 0"/>
  </joint>
  <link name="left_base_link">
    <inertial>
      <origin rpy="0 0 0" xyz="-0.00319465997 -0.00005467608 0.04321758463"/>
      <mass value="1.06458435"/>
      <inertia ixx="0.00102659855152" ixy="0.00000186219753" ixz="-0.00000295298037" iyy="0.00114399299508" iyz="-0.00000078763492" izz="0.00090872933022"/>
    </inertial>
    <visual>
      <origin rpy="0 0 0" xyz="0 0 0"/>
      <geometry>
        <mesh filename="package://nero_description/meshes/dae/base_link.dae"/>
      </geometry>
    </visual>
    <collision>
      <origin rpy="0 0 0" xyz="0 0 0"/>
      <geometry>
        <mesh filename="package://nero_description/meshes/base_link.stl"/>
      </geometry>
    </collision>
  </link>
  <link name="left_link1">
    <inertial>
      <origin rpy="0 0 0" xyz="-0.00076810578 -0.00005718031 -0.00686372765"/>
      <mass value="0.76710504"/>
      <inertia ixx="0.00066689512233" ixy="0.00000273938306" ixz="0.00001463284987" iyy="0.00054501235592" iyz="0.00000183168344" izz="0.00051509465737"/>
    </inertial>
    <visual>
      <origin rpy="0 0 0" xyz="0 0 0"/>
      <geometry>
        <mesh filename="package://nero_description/meshes/dae/link1.dae"/>
      </geometry>
    </visual>
    <collision>
      <origin rpy="0 0 0" xyz="0 0 0"/>
      <geometry>
        <mesh filename="package://nero_description/meshes/link1.stl"/>
      </geometry>
    </collision>
  </link>
  <joint name="left_joint1" type="revolute">
    <origin rpy="0 0 0" xyz="0 0 0.138"/>
    <parent link="left_base_link"/>
    <child link="left_link1"/>
    <axis xyz="0 0 1"/>
    <!-- joint1 限制（关键）：
      左臂允许为负，但上限限制为 +10deg，避免进入导致肘部朝向不期望的域。 -->
    <limit effort="100" lower="-2.70526" upper="0.1745329252" velocity="5"/>
  </joint>
  <link name="left_link2">
    <inertial>
      <origin rpy="0 0 0" xyz="0.00079686657 -0.07890325930 0.00111849422"/>
      <mass value="0.69381908"/>
      <inertia ixx="0.00201093857656" ixy="-0.00002399426785" ixz="-0.00000072824714" iyy="0.00063544232555" iyz="0.00005831284343" izz="0.00181943989593"/>
    </inertial>
    <visual>
      <origin rpy="0 0 0" xyz="0 0 0"/>
      <geometry>
        <mesh filename="package://nero_description/meshes/dae/link2.dae"/>
      </geometry>
    </visual>
    <collision>
      <origin rpy="0 0 0" xyz="0 0 0"/>
      <geometry>
        <mesh filename="package://nero_description/meshes/link2.stl"/>
      </geometry>
    </collision>
  </link>
  <joint name="left_joint2" type="revolute">
    <origin rpy="1.5707963  3.1415926 0" xyz="0 0 0"/>
    <parent link="left_link1"/>
    <child link="left_link2"/>
    <axis xyz="0 0 1"/>
    <!-- joint2: lower=-60 deg (-pi/3 rad), upper=1.74 rad -->
    <limit effort="100" lower="-1.0471975512" upper="1.74" velocity="5"/>
  </joint>
  <link name="left_link3">
    <inertial>
      <origin rpy="0 0 0" xyz="0.00014513363 -0.00121378766 -0.04861136795"/>
      <mass value="0.67246544"/>
      <inertia ixx="0.00343229961910" ixy="-0.00000026976739" ixz="0.00000305078107" iyy="0.00338662526897" iyz="-0.00003550220027" izz="0.00028853579710"/>
    </inertial>
    <visual>
      <origin rpy="0 0 0" xyz="0 0 0"/>
      <geometry>
        <mesh filename="package://nero_description/meshes/dae/link3.dae"/>
      </geometry>
    </visual>
    <collision>
      <origin rpy="0 0 0" xyz="0 0 0"/>
      <geometry>
        <mesh filename="package://nero_description/meshes/link3.stl"/>
      </geometry>
    </collision>
  </link>
  <joint name="left_joint3" type="revolute">
    <origin rpy="-1.5707963  0 3.1415926926" xyz="0 -0.31 0"/>
    <parent link="left_link2"/>
    <child link="left_link3"/>
    <axis xyz="0 0 1"/>
    <!-- joint3: 左右对称全范围 [-2.75, 2.75] rad -->
    <limit effort="100" lower="-2.75" upper="2.75" velocity="5"/>
  </joint>
  <link name="left_link4">
    <inertial>
      <origin rpy="0 0 0" xyz="-0.00031334623 -0.05675192422 0.00076056133"/>
      <mass value="0.48451414"/>
      <inertia ixx="0.00050386693505" ixy="-0.00000529675237" ixz="0.00000006134740" iyy="0.00023502068202" iyz="0.00001815932566" izz="0.00040149523118"/>
    </inertial>
    <visual>
      <origin rpy="0 0 0" xyz="0 0 0"/>
      <geometry>
        <mesh filename="package://nero_description/meshes/dae/link4.dae"/>
      </geometry>
    </visual>
    <collision>
      <origin rpy="0 0 0" xyz="0 0 0"/>
      <geometry>
        <mesh filename="package://nero_description/meshes/link4.stl"/>
      </geometry>
    </collision>
  </link>
  <joint name="left_joint4" type="revolute">
    <origin rpy="-1.5707963  0 3.1415926926" xyz="0 0 0"/>
    <parent link="left_link3"/>
    <child link="left_link4"/>
    <axis xyz="0 0 1"/>
    <!-- joint4 只允许非负（保留 eps 避免贴 0） -->
    <limit effort="100" lower="0.001" upper="2.14" velocity="5"/>
  </joint>
  <link name="left_link5">
    <inertial>
      <origin rpy="0 0 0" xyz="0.00265591357 0.00201195753 -0.11620855434"/>
      <mass value="0.58368405"/>
      <inertia ixx="0.00089537686723" ixy="0.00000648218232" ixz="-0.00001463346849" iyy="0.00085866122972" iyz="-0.00004035185637" izz="0.00021774946532"/>
    </inertial>
    <visual>
      <origin rpy="0 0 0" xyz="0 0 0"/>
      <geometry>
        <mesh filename="package://nero_description/meshes/dae/link5.dae"/>
      </geometry>
    </visual>
    <collision>
      <origin rpy="0 0 0" xyz="0 0 0"/>
      <geometry>
        <mesh filename="package://nero_description/meshes/link5.stl"/>
      </geometry>
    </collision>
  </link>
  <joint name="left_joint5" type="revolute">
    <origin rpy="1.5707963  -1.5707963  0" xyz="0 -0.27001 0"/>
    <parent link="left_link4"/>
    <child link="left_link5"/>
    <axis xyz="0 0 1"/>
    <!-- joint5 限制（关键）：
      左臂不允许为负角度：lower=eps（避免贴 0）。 -->
    <limit effort="100" lower="0.001" upper="2.75" velocity="5"/>
  </joint>
  <link name="left_link6">
    <inertial>
      <origin rpy="0 0 0" xyz="0.00009501505 0.00107831174 -0.00019110990"/>
      <mass value="0.3140406"/>
      <inertia ixx="0.00006027211661" ixy="-0.00000024650903" ixz="0.00000015701294" iyy="0.00004699514792" iyz="0.00000004170875" izz="0.00005756771792"/>
    </inertial>
    <visual>
      <origin rpy="0 0 0" xyz="0 0 0"/>
      <geometry>
        <mesh filename="package://nero_description/meshes/dae/link6.dae"/>
      </geometry>
    </visual>
    <collision>
      <origin rpy="0 0 0" xyz="0 0 0"/>
      <geometry>
        <mesh filename="package://nero_description/meshes/link6.stl"/>
      </geometry>
    </collision>
  </link>
  <joint name="left_joint6" type="revolute">
    <origin rpy="1.5707963  -1.5707963  0" xyz="0 0 0"/>
    <parent link="left_link5"/>
    <child link="left_link6"/>
    <axis xyz="0 0 1"/>
    <limit effort="100" lower="-0.73" upper="0.95" velocity="5"/>
  </joint>
  <link name="left_link7">
    <inertial>
      <origin rpy="0 0 0" xyz="-0.00014000 -0.00010000 -0.00275000"/>
      <mass value="0.000001"/>
      <inertia ixx="1.1000000000000001e-07" ixy="0" ixz="0" iyy="1.1000000000000001e-07" iyz="0" izz="1.9999999999999999e-07"/>
    </inertial>
    <visual>
      <origin rpy="0 0 0" xyz="0 0 0"/>
      <geometry>
        <mesh filename="package://nero_description/meshes/dae/link7.dae"/>
      </geometry>
    </visual>
    <collision>
      <origin rpy="0 0 0" xyz="0 0 0"/>
      <geometry>
        <mesh filename="package://nero_description/meshes/link7.stl"/>
      </geometry>
    </collision>
  </link>
  <joint name="left_joint7" type="revolute">
    <origin rpy="1.5707963 0 0" xyz="0 -0.0235 0"/>
    <parent link="left_link6"/>
    <child link="left_link7"/>
    <axis xyz="0 0 1"/>
    <limit effort="100" lower="-1.5707963" upper="1.5707963" velocity="5"/>
  </joint>
  <!-- 将单臂基座挂载到父 link（装配入口） -->
  <joint name="right_mount_joint" type="fixed">
    <parent link="body"/>
    <child link="right_base_link"/>
    <origin rpy="0 -1.5707926 1.5707926" xyz="0 -0.20 0"/>
  </joint>
  <link name="right_base_link">
    <inertial>
      <origin rpy="0 0 0" xyz="-0.00319465997 -0.00005467608 0.04321758463"/>
      <mass value="1.06458435"/>
      <inertia ixx="0.00102659855152" ixy="0.00000186219753" ixz="-0.00000295298037" iyy="0.00114399299508" iyz="-0.00000078763492" izz="0.00090872933022"/>
    </inertial>
    <visual>
      <origin rpy="0 0 0" xyz="0 0 0"/>
      <geometry>
        <mesh filename="package://nero_description/meshes/dae/base_link.dae"/>
      </geometry>
    </visual>
    <collision>
      <origin rpy="0 0 0" xyz="0 0 0"/>
      <geometry>
        <mesh filename="package://nero_description/meshes/base_link.stl"/>
      </geometry>
    </collision>
  </link>
  <link name="right_link1">
    <inertial>
      <origin rpy="0 0 0" xyz="-0.00076810578 -0.00005718031 -0.00686372765"/>
      <mass value="0.76710504"/>
      <inertia ixx="0.00066689512233" ixy="0.00000273938306" ixz="0.00001463284987" iyy="0.00054501235592" iyz="0.00000183168344" izz="0.00051509465737"/>
    </inertial>
    <visual>
      <origin rpy="0 0 0" xyz="0 0 0"/>
      <geometry>
        <mesh filename="package://nero_description/meshes/dae/link1.dae"/>
      </geometry>
    </visual>
    <collision>
      <origin rpy="0 0 0" xyz="0 0 0"/>
      <geometry>
        <mesh filename="package://nero_description/meshes/link1.stl"/>
      </geometry>
    </collision>
  </link>
  <joint name="right_joint1" type="revolute">
    <origin rpy="0 0 0" xyz="0 0 0.138"/>
    <parent link="right_base_link"/>
    <child link="right_link1"/>
    <axis xyz="0 0 1"/>
    <!-- joint1 限制（关键）：
      右臂允许为正，但下限限制为 -60deg（不能小于 -60deg）。 -->
    <limit effort="100" lower="-1.0471975512" upper="2.70526" velocity="5"/>
  </joint>
  <link name="right_link2">
    <inertial>
      <origin rpy="0 0 0" xyz="0.00079686657 -0.07890325930 0.00111849422"/>
      <mass value="0.69381908"/>
      <inertia ixx="0.00201093857656" ixy="-0.00002399426785" ixz="-0.00000072824714" iyy="0.00063544232555" iyz="0.00005831284343" izz="0.00181943989593"/>
    </inertial>
    <visual>
      <origin rpy="0 0 0" xyz="0 0 0"/>
      <geometry>
        <mesh filename="package://nero_description/meshes/dae/link2.dae"/>
      </geometry>
    </visual>
    <collision>
      <origin rpy="0 0 0" xyz="0 0 0"/>
      <geometry>
        <mesh filename="package://nero_description/meshes/link2.stl"/>
      </geometry>
    </collision>
  </link>
  <joint name="right_joint2" type="revolute">
    <origin rpy="1.5707963  3.1415926 0" xyz="0 0 0"/>
    <parent link="right_link1"/>
    <child link="right_link2"/>
    <axis xyz="0 0 1"/>
    <!-- joint2: lower=-60 deg (-pi/3 rad), upper=1.74 rad -->
    <limit effort="100" lower="-1.0471975512" upper="1.74" velocity="5"/>
  </joint>
  <link name="right_link3">
    <inertial>
      <origin rpy="0 0 0" xyz="0.00014513363 -0.00121378766 -0.04861136795"/>
      <mass value="0.67246544"/>
      <inertia ixx="0.00343229961910" ixy="-0.00000026976739" ixz="0.00000305078107" iyy="0.00338662526897" iyz="-0.00003550220027" izz="0.00028853579710"/>
    </inertial>
    <visual>
      <origin rpy="0 0 0" xyz="0 0 0"/>
      <geometry>
        <mesh filename="package://nero_description/meshes/dae/link3.dae"/>
      </geometry>
    </visual>
    <collision>
      <origin rpy="0 0 0" xyz="0 0 0"/>
      <geometry>
        <mesh filename="package://nero_description/meshes/link3.stl"/>
      </geometry>
    </collision>
  </link>
  <joint name="right_joint3" type="revolute">
    <origin rpy="-1.5707963  0 3.1415926926" xyz="0 -0.31 0"/>
    <parent link="right_link2"/>
    <child link="right_link3"/>
    <axis xyz="0 0 1"/>
    <!-- joint3: 左右对称全范围 [-2.75, 2.75] rad -->
    <limit effort="100" lower="-2.75" upper="2.75" velocity="5"/>
  </joint>
  <link name="right_link4">
    <inertial>
      <origin rpy="0 0 0" xyz="-0.00031334623 -0.05675192422 0.00076056133"/>
      <mass value="0.48451414"/>
      <inertia ixx="0.00050386693505" ixy="-0.00000529675237" ixz="0.00000006134740" iyy="0.00023502068202" iyz="0.00001815932566" izz="0.00040149523118"/>
    </inertial>
    <visual>
      <origin rpy="0 0 0" xyz="0 0 0"/>
      <geometry>
        <mesh filename="package://nero_description/meshes/dae/link4.dae"/>
      </geometry>
    </visual>
    <collision>
      <origin rpy="0 0 0" xyz="0 0 0"/>
      <geometry>
        <mesh filename="package://nero_description/meshes/link4.stl"/>
      </geometry>
    </collision>
  </link>
  <joint name="right_joint4" type="revolute">
    <origin rpy="-1.5707963  0 3.1415926926" xyz="0 0 0"/>
    <parent link="right_link3"/>
    <child link="right_link4"/>
    <axis xyz="0 0 1"/>
    <!-- joint4 只允许非负（保留 eps 避免贴 0） -->
    <limit effort="100" lower="0.001" upper="2.14" velocity="5"/>
  </joint>
  <link name="right_link5">
    <inertial>
      <origin rpy="0 0 0" xyz="0.00265591357 0.00201195753 -0.11620855434"/>
      <mass value="0.58368405"/>
      <inertia ixx="0.00089537686723" ixy="0.00000648218232" ixz="-0.00001463346849" iyy="0.00085866122972" iyz="-0.00004035185637" izz="0.00021774946532"/>
    </inertial>
    <visual>
      <origin rpy="0 0 0" xyz="0 0 0"/>
      <geometry>
        <mesh filename="package://nero_description/meshes/dae/link5.dae"/>
      </geometry>
    </visual>
    <collision>
      <origin rpy="0 0 0" xyz="0 0 0"/>
      <geometry>
        <mesh filename="package://nero_description/meshes/link5.stl"/>
      </geometry>
    </collision>
  </link>
  <joint name="right_joint5" type="revolute">
    <origin rpy="1.5707963  -1.5707963  0" xyz="0 -0.27001 0"/>
    <parent link="right_link4"/>
    <child link="right_link5"/>
    <axis xyz="0 0 1"/>
    <!-- joint5 限制（关键）：
      右臂不允许为正角度：upper=-eps（避免贴 0）。 -->
    <limit effort="100" lower="-2.75" upper="-0.001" velocity="5"/>
  </joint>
  <link name="right_link6">
    <inertial>
      <origin rpy="0 0 0" xyz="0.00009501505 0.00107831174 -0.00019110990"/>
      <mass value="0.3140406"/>
      <inertia ixx="0.00006027211661" ixy="-0.00000024650903" ixz="0.00000015701294" iyy="0.00004699514792" iyz="0.00000004170875" izz="0.00005756771792"/>
    </inertial>
    <visual>
      <origin rpy="0 0 0" xyz="0 0 0"/>
      <geometry>
        <mesh filename="package://nero_description/meshes/dae/link6.dae"/>
      </geometry>
    </visual>
    <collision>
      <origin rpy="0 0 0" xyz="0 0 0"/>
      <geometry>
        <mesh filename="package://nero_description/meshes/link6.stl"/>
      </geometry>
    </collision>
  </link>
  <joint name="right_joint6" type="revolute">
    <origin rpy="1.5707963  -1.5707963  0" xyz="0 0 0"/>
    <parent link="right_link5"/>
    <child link="right_link6"/>
    <axis xyz="0 0 1"/>
    <limit effort="100" lower="-0.73" upper="0.95" velocity="5"/>
  </joint>
  <link name="right_link7">
    <inertial>
      <origin rpy="0 0 0" xyz="-0.00014000 -0.00010000 -0.00275000"/>
      <mass value="0.000001"/>
      <inertia ixx="1.1000000000000001e-07" ixy="0" ixz="0" iyy="1.1000000000000001e-07" iyz="0" izz="1.9999999999999999e-07"/>
    </inertial>
    <visual>
      <origin rpy="0 0 0" xyz="0 0 0"/>
      <geometry>
        <mesh filename="package://nero_description/meshes/dae/link7.dae"/>
      </geometry>
    </visual>
    <collision>
      <origin rpy="0 0 0" xyz="0 0 0"/>
      <geometry>
        <mesh filename="package://nero_description/meshes/link7.stl"/>
      </geometry>
    </collision>
  </link>
  <joint name="right_joint7" type="revolute">
    <origin rpy="1.5707963 0 0" xyz="0 -0.0235 0"/>
    <parent link="right_link6"/>
    <child link="right_link7"/>
    <axis xyz="0 0 1"/>
    <limit effort="100" lower="-1.5707963" upper="1.5707963" velocity="5"/>
  </joint>
</robot>
