<?xml version="1.0" ?>
<!-- =================================================================================== -->
<!-- |    This document was autogenerated by xacro from /home/zhouqiangong/agx_arm_ws/src/nero-dual-arm/src/agx_arm_urdf/nero/urdf/nero_dual_arm_with_gripper_description.xacro | -->
<!-- |    EDITING THIS FILE BY HAND IS NOT RECOMMENDED                                 | -->
<!-- =================================================================================== -->
<robot name="nero_dual_arm_with_gripper">
  <link name="world"/>
  <link name="body"/>
  <joint name="world_to_body" type="fixed">
    <parent link="world"/>
    <child link="body"/>
    <origin rpy="0 0 0" xyz="0 0 0"/>
  </joint>
  <!-- 将单臂基座挂载到父 link（装配入口） -->
  <joint name="left_mount_joint" type="fixed">
    <parent link="body"/>
    <child link="left_base_link"/>
    <origin rpy="0 -1.5707926 -1.5707926" xyz="0 0.194 0"/>
  </joint>
  <link name="left_base_link">
    <inertial>
      <origin rpy="0 0 0" xyz="-0.00319465997 -0.00005467608 0.04321758463"/>
      <mass value="1.06458435"/>
      <inertia ixx="0.00102659855152" ixy="0.00000186219753" ixz="-0.00000295298037" iyy="0.00114399299508" iyz="-0.00000078763492" izz="0.00090872933022"/>
    </inertial>
    <visual>
      <origin rpy="0 0 0" xyz="0 0 0"/>
      <geometry>
        <mesh filename="package://nero_description/meshes/dae/base_link.dae"/>
      </geometry>
    </visual>
    <collision>
      <origin rpy="0 0 0" xyz="0 0 0"/>
      <geometry>
        <mesh filename="package://nero_description/meshes/base_link.stl"/>
      </geometry>
    </collision>
  </link>
  <link name="left_link1">
    <inertial>
      <origin rpy="0 0 0" xyz="-0.00076810578 -0.00005718031 -0.00686372765"/>
      <mass value="0.76710504"/>
      <inertia ixx="0.00066689512233" ixy="0.00000273938306" ixz="0.00001463284987" iyy="0.00054501235592" iyz="0.00000183168344" izz="0.00051509465737"/>
    </inertial>
    <visual>
      <origin rpy="0 0 0" xyz="0 0 0"/>
      <geometry>
        <mesh filename="package://nero_description/meshes/dae/link1.dae"/>
      </geometry>
    </visual>
    <collision>
      <origin rpy="0 0 0" xyz="0 0 0"/>
      <geometry>
        <mesh filename="package://nero_description/meshes/link1.stl"/>
      </geometry>
    </collision>
  </link>
  <joint name="left_joint1" type="revolute">
    <origin rpy="0 0 0" xyz="0 0 0.138"/>
    <parent link="left_base_link"/>
    <child link="left_link1"/>
    <axis xyz="0 0 1"/>
    <limit effort="100" lower="-2.70526" upper="1.0471975512" velocity="5"/>
  </joint>
  <link name="left_link2">
    <inertial>
      <origin rpy="0 0 0" xyz="0.00079686657 -0.07890325930 0.00111849422"/>
      <mass value="0.69381908"/>
      <inertia ixx="0.00201093857656" ixy="-0.00002399426785" ixz="-0.00000072824714" iyy="0.00063544232555" iyz="0.00005831284343" izz="0.00181943989593"/>
    </inertial>
    <visual>
      <origin rpy="0 0 0" xyz="0 0 0"/>
      <geometry>
        <mesh filename="package://nero_description/meshes/dae/link2.dae"/>
      </geometry>
    </visual>
    <collision>
      <origin rpy="0 0 0" xyz="0 0 0"/>
      <geometry>
        <mesh filename="package://nero_description/meshes/link2.stl"/>
      </geometry>
    </collision>
  </link>
  <joint name="left_joint2" type="revolute">
    <origin rpy="1.5707963  3.1415926 0" xyz="0 0 0"/>
    <parent link="left_link1"/>
    <child link="left_link2"/>
    <axis xyz="0 0 1"/>
    <!-- joint2: lower=-0 deg (-pi/3 rad), upper=1.74 rad -->
    <limit effort="100" lower="-0.0001" upper="1.74" velocity="5"/>
  </joint>
  <link name="left_link3">
    <inertial>
      <origin rpy="0 0 0" xyz="0.00014513363 -0.00121378766 -0.04861136795"/>
      <mass value="0.67246544"/>
      <inertia ixx="0.00343229961910" ixy="-0.00000026976739" ixz="0.00000305078107" iyy="0.00338662526897" iyz="-0.00003550220027" izz="0.00028853579710"/>
    </inertial>
    <visual>
      <origin rpy="0 0 0" xyz="0 0 0"/>
      <geometry>
        <mesh filename="package://nero_description/meshes/dae/link3.dae"/>
      </geometry>
    </visual>
    <collision>
      <origin rpy="0 0 0" xyz="0 0 0"/>
      <geometry>
        <mesh filename="package://nero_description/meshes/link3.stl"/>
      </geometry>
    </collision>
  </link>
  <joint name="left_joint3" type="revolute">
    <origin rpy="-1.5707963  0 3.1415926926" xyz="0 -0.31 0"/>
    <parent link="left_link2"/>
    <child link="left_link3"/>
    <axis xyz="0 0 1"/>
    <!-- joint3: 左右对称全范围 [-2.75, 2.75] rad -->
    <limit effort="100" lower="-2.75" upper="2.75" velocity="5"/>
  </joint>
  <link name="left_link4">
    <inertial>
      <origin rpy="0 0 0" xyz="-0.00031334623 -0.05675192422 0.00076056133"/>
      <mass value="0.48451414"/>
      <inertia ixx="0.00050386693505" ixy="-0.00000529675237" ixz="0.00000006134740" iyy="0.00023502068202" iyz="0.00001815932566" izz="0.00040149523118"/>
    </inertial>
    <visual>
      <origin rpy="0 0 0" xyz="0 0 0"/>
      <geometry>
        <mesh filename="package://nero_description/meshes/dae/link4.dae"/>
      </geometry>
    </visual>
    <collision>
      <origin rpy="0 0 0" xyz="0 0 0"/>
      <geometry>
        <mesh filename="package://nero_description/meshes/link4.stl"/>
      </geometry>
    </collision>
  </link>
  <joint name="left_joint4" type="revolute">
    <origin rpy="-1.5707963  0 3.1415926926" xyz="0 0 0"/>
    <parent link="left_link3"/>
    <child link="left_link4"/>
    <axis xyz="0 0 1"/>
    <!-- joint4：非负约束以减少肘部翻转分支；lower/upper 由 joint4_lower/joint4_upper 传入 -->
    <limit effort="100" lower="0.001" upper="2.14" velocity="5"/>
  </joint>
  <link name="left_link5">
    <inertial>
      <origin rpy="0 0 0" xyz="0.00265591357 0.00201195753 -0.11620855434"/>
      <mass value="0.58368405"/>
      <inertia ixx="0.00089537686723" ixy="0.00000648218232" ixz="-0.00001463346849" iyy="0.00085866122972" iyz="-0.00004035185637" izz="0.00021774946532"/>
    </inertial>
    <visual>
      <origin rpy="0 0 0" xyz="0 0 0"/>
      <geometry>
        <mesh filename="package://nero_description/meshes/dae/link5.dae"/>
      </geometry>
    </visual>
    <collision>
      <origin rpy="0 0 0" xyz="0 0 0"/>
      <geometry>
        <mesh filename="package://nero_description/meshes/link5.stl"/>
      </geometry>
    </collision>
  </link>
  <joint name="left_joint5" type="revolute">
    <origin rpy="1.5707963  -1.5707963  0" xyz="0 -0.27001 0"/>
    <parent link="left_link4"/>
    <child link="left_link5"/>
    <axis xyz="0 0 1"/>
    <limit effort="100" lower="-2.75" upper="2.75" velocity="5"/>
  </joint>
  <link name="left_link6">
    <inertial>
      <origin rpy="0 0 0" xyz="0.00009501505 0.00107831174 -0.00019110990"/>
      <mass value="0.3140406"/>
      <inertia ixx="0.00006027211661" ixy="-0.00000024650903" ixz="0.00000015701294" iyy="0.00004699514792" iyz="0.00000004170875" izz="0.00005756771792"/>
    </inertial>
    <visual>
      <origin rpy="0 0 0" xyz="0 0 0"/>
      <geometry>
        <mesh filename="package://nero_description/meshes/dae/link6.dae"/>
      </geometry>
    </visual>
    <collision>
      <origin rpy="0 0 0" xyz="0 0 0"/>
      <geometry>
        <mesh filename="package://nero_description/meshes/link6.stl"/>
      </geometry>
    </collision>
  </link>
  <joint name="left_joint6" type="revolute">
    <origin rpy="1.5707963  -1.5707963  0" xyz="0 0 0"/>
    <parent link="left_link5"/>
    <child link="left_link6"/>
    <axis xyz="0 0 1"/>
    <limit effort="100" lower="-0.73" upper="0.95" velocity="5"/>
  </joint>
  <link name="left_link7">
    <inertial>
      <origin rpy="0 0 0" xyz="-0.00014000 -0.00010000 -0.00275000"/>
      <mass value="0.000001"/>
      <inertia ixx="1.1000000000000001e-07" ixy="0" ixz="0" iyy="1.1000000000000001e-07" iyz="0" izz="1.9999999999999999e-07"/>
    </inertial>
    <visual>
      <origin rpy="0 0 0" xyz="0 0 0"/>
      <geometry>
        <mesh filename="package://nero_description/meshes/dae/link7.dae"/>
      </geometry>
    </visual>
    <collision>
      <origin rpy="0 0 0" xyz="0 0 0"/>
      <geometry>
        <mesh filename="package://nero_description/meshes/link7.stl"/>
      </geometry>
    </collision>
  </link>
  <joint name="left_joint7" type="revolute">
    <origin rpy="1.5707963 0 0" xyz="0 -0.0235 0"/>
    <parent link="left_link6"/>
    <child link="left_link7"/>
    <axis xyz="0 0 1"/>
    <limit effort="100" lower="-1.5707963" upper="1.5707963" velocity="5"/>
  </joint>
  <!-- 将单臂基座挂载到父 link（装配入口） -->
  <joint name="right_mount_joint" type="fixed">
    <parent link="body"/>
    <child link="right_base_link"/>
    <origin rpy="0 -1.5707926 1.5707926" xyz="0 -0.194 0"/>
  </joint>
  <link name="right_base_link">
    <inertial>
      <origin rpy="0 0 0" xyz="-0.00319465997 -0.00005467608 0.04321758463"/>
      <mass value="1.06458435"/>
      <inertia ixx="0.00102659855152" ixy="0.00000186219753" ixz="-0.00000295298037" iyy="0.00114399299508" iyz="-0.00000078763492" izz="0.00090872933022"/>
    </inertial>
    <visual>
      <origin rpy="0 0 0" xyz="0 0 0"/>
      <geometry>
        <mesh filename="package://nero_description/meshes/dae/base_link.dae"/>
      </geometry>
    </visual>
    <collision>
      <origin rpy="0 0 0" xyz="0 0 0"/>
      <geometry>
        <mesh filename="package://nero_description/meshes/base_link.stl"/>
      </geometry>
    </collision>
  </link>
  <link name="right_link1">
    <inertial>
      <origin rpy="0 0 0" xyz="-0.00076810578 -0.00005718031 -0.00686372765"/>
      <mass value="0.76710504"/>
      <inertia ixx="0.00066689512233" ixy="0.00000273938306" ixz="0.00001463284987" iyy="0.00054501235592" iyz="0.00000183168344" izz="0.00051509465737"/>
    </inertial>
    <visual>
      <origin rpy="0 0 0" xyz="0 0 0"/>
      <geometry>
        <mesh filename="package://nero_description/meshes/dae/link1.dae"/>
      </geometry>
    </visual>
    <collision>
      <origin rpy="0 0 0" xyz="0 0 0"/>
      <geometry>
        <mesh filename="package://nero_description/meshes/link1.stl"/>
      </geometry>
    </collision>
  </link>
  <joint name="right_joint1" type="revolute">
    <origin rpy="0 0 0" xyz="0 0 0.138"/>
    <parent link="right_base_link"/>
    <child link="right_link1"/>
    <axis xyz="0 0 1"/>
    <limit effort="100" lower="-1.0471975512" upper="2.70526" velocity="5"/>
  </joint>
  <link name="right_link2">
    <inertial>
      <origin rpy="0 0 0" xyz="0.00079686657 -0.07890325930 0.00111849422"/>
      <mass value="0.69381908"/>
      <inertia ixx="0.00201093857656" ixy="-0.00002399426785" ixz="-0.00000072824714" iyy="0.00063544232555" iyz="0.00005831284343" izz="0.00181943989593"/>
    </inertial>
    <visual>
      <origin rpy="0 0 0" xyz="0 0 0"/>
      <geometry>
        <mesh filename="package://nero_description/meshes/dae/link2.dae"/>
      </geometry>
    </visual>
    <collision>
      <origin rpy="0 0 0" xyz="0 0 0"/>
      <geometry>
        <mesh filename="package://nero_description/meshes/link2.stl"/>
      </geometry>
    </collision>
  </link>
  <joint name="right_joint2" type="revolute">
    <origin rpy="1.5707963  3.1415926 0" xyz="0 0 0"/>
    <parent link="right_link1"/>
    <child link="right_link2"/>
    <axis xyz="0 0 1"/>
    <!-- joint2: lower=-1.74 rad, upper= 0 rad -->
    <limit effort="100" lower="-0.0001" upper="1.74" velocity="5"/>
  </joint>
  <link name="right_link3">
    <inertial>
      <origin rpy="0 0 0" xyz="0.00014513363 -0.00121378766 -0.04861136795"/>
      <mass value="0.67246544"/>
      <inertia ixx="0.00343229961910" ixy="-0.00000026976739" ixz="0.00000305078107" iyy="0.00338662526897" iyz="-0.00003550220027" izz="0.00028853579710"/>
    </inertial>
    <visual>
      <origin rpy="0 0 0" xyz="0 0 0"/>
      <geometry>
        <mesh filename="package://nero_description/meshes/dae/link3.dae"/>
      </geometry>
    </visual>
    <collision>
      <origin rpy="0 0 0" xyz="0 0 0"/>
      <geometry>
        <mesh filename="package://nero_description/meshes/link3.stl"/>
      </geometry>
    </collision>
  </link>
  <joint name="right_joint3" type="revolute">
    <origin rpy="-1.5707963  0 3.1415926926" xyz="0 -0.31 0"/>
    <parent link="right_link2"/>
    <child link="right_link3"/>
    <axis xyz="0 0 1"/>
    <!-- joint3: 左右对称全范围 [-2.75, 2.75] rad -->
    <limit effort="100" lower="-2.75" upper="2.75" velocity="5"/>
  </joint>
  <link name="right_link4">
    <inertial>
      <origin rpy="0 0 0" xyz="-0.00031334623 -0.05675192422 0.00076056133"/>
      <mass value="0.48451414"/>
      <inertia ixx="0.00050386693505" ixy="-0.00000529675237" ixz="0.00000006134740" iyy="0.00023502068202" iyz="0.00001815932566" izz="0.00040149523118"/>
    </inertial>
    <visual>
      <origin rpy="0 0 0" xyz="0 0 0"/>
      <geometry>
        <mesh filename="package://nero_description/meshes/dae/link4.dae"/>
      </geometry>
    </visual>
    <collision>
      <origin rpy="0 0 0" xyz="0 0 0"/>
      <geometry>
        <mesh filename="package://nero_description/meshes/link4.stl"/>
      </geometry>
    </collision>
  </link>
  <joint name="right_joint4" type="revolute">
    <origin rpy="-1.5707963  0 3.1415926926" xyz="0 0 0"/>
    <parent link="right_link3"/>
    <child link="right_link4"/>
    <axis xyz="0 0 1"/>
    <!-- joint4：非负约束以减少肘部翻转分支；lower/upper 由 joint4_lower/joint4_upper 传入 -->
    <limit effort="100" lower="0.001" upper="2.14" velocity="5"/>
  </joint>
  <link name="right_link5">
    <inertial>
      <origin rpy="0 0 0" xyz="0.00265591357 0.00201195753 -0.11620855434"/>
      <mass value="0.58368405"/>
      <inertia ixx="0.00089537686723" ixy="0.00000648218232" ixz="-0.00001463346849" iyy="0.00085866122972" iyz="-0.00004035185637" izz="0.00021774946532"/>
    </inertial>
    <visual>
      <origin rpy="0 0 0" xyz="0 0 0"/>
      <geometry>
        <mesh filename="package://nero_description/meshes/dae/link5.dae"/>
      </geometry>
    </visual>
    <collision>
      <origin rpy="0 0 0" xyz="0 0 0"/>
      <geometry>
        <mesh filename="package://nero_description/meshes/link5.stl"/>
      </geometry>
    </collision>
  </link>
  <joint name="right_joint5" type="revolute">
    <origin rpy="1.5707963  -1.5707963  0" xyz="0 -0.27001 0"/>
    <parent link="right_link4"/>
    <child link="right_link5"/>
    <axis xyz="0 0 1"/>
    <limit effort="100" lower="-2.75" upper="2.75" velocity="5"/>
  </joint>
  <link name="right_link6">
    <inertial>
      <origin rpy="0 0 0" xyz="0.00009501505 0.00107831174 -0.00019110990"/>
      <mass value="0.3140406"/>
      <inertia ixx="0.00006027211661" ixy="-0.00000024650903" ixz="0.00000015701294" iyy="0.00004699514792" iyz="0.00000004170875" izz="0.00005756771792"/>
    </inertial>
    <visual>
      <origin rpy="0 0 0" xyz="0 0 0"/>
      <geometry>
        <mesh filename="package://nero_description/meshes/dae/link6.dae"/>
      </geometry>
    </visual>
    <collision>
      <origin rpy="0 0 0" xyz="0 0 0"/>
      <geometry>
        <mesh filename="package://nero_description/meshes/link6.stl"/>
      </geometry>
    </collision>
  </link>
  <joint name="right_joint6" type="revolute">
    <origin rpy="1.5707963  -1.5707963  0" xyz="0 0 0"/>
    <parent link="right_link5"/>
    <child link="right_link6"/>
    <axis xyz="0 0 1"/>
    <limit effort="100" lower="-0.73" upper="0.95" velocity="5"/>
  </joint>
  <link name="right_link7">
    <inertial>
      <origin rpy="0 0 0" xyz="-0.00014000 -0.00010000 -0.00275000"/>
      <mass value="0.000001"/>
      <inertia ixx="1.1000000000000001e-07" ixy="0" ixz="0" iyy="1.1000000000000001e-07" iyz="0" izz="1.9999999999999999e-07"/>
    </inertial>
    <visual>
      <origin rpy="0 0 0" xyz="0 0 0"/>
      <geometry>
        <mesh filename="package://nero_description/meshes/dae/link7.dae"/>
      </geometry>
    </visual>
    <collision>
      <origin rpy="0 0 0" xyz="0 0 0"/>
      <geometry>
        <mesh filename="package://nero_description/meshes/link7.stl"/>
      </geometry>
    </collision>
  </link>
  <joint name="right_joint7" type="revolute">
    <origin rpy="1.5707963 0 0" xyz="0 -0.0235 0"/>
    <parent link="right_link6"/>
    <child link="right_link7"/>
    <axis xyz="0 0 1"/>
    <limit effort="100" lower="-1.5707963" upper="1.5707963" velocity="5"/>
  </joint>
  <link name="left_gripper_flange">
    <inertial>
      <origin rpy="0 0 0" xyz="0.0 0.0 -0.00032"/>
      <mass value="0.04771096"/>
      <inertia ixx="2.697e-05" ixy="0" ixz="0" iyy="4.311e-05" iyz="0" izz="2.479e-05"/>
    </inertial>
    <visual>
      <origin rpy="0 0 0" xyz="0 0 0"/>
      <geometry>
        <mesh filename="package://nero_description/meshes/dae/gripper_flange.dae"/>
      </geometry>
    </visual>
    <collision>
      <origin rpy="0 0 0" xyz="0 0 0"/>
      <geometry>
        <mesh filename="package://nero_description/meshes/gripper_flange.stl"/>
      </geometry>
    </collision>
  </link>
  <joint name="left_gripper_flange_joint" type="fixed">
    <parent link="left_link7"/>
    <child link="left_gripper_flange"/>
    <origin rpy="-1.5708 0 -1.5708" xyz="0.032 0 -0.0235"/>
  </joint>
  <link name="left_gripper_base">
    <inertial>
      <origin rpy="0 0 0" xyz="-0.000183807162235591 8.05033155577911E-05 0.0321436689908876"/>
      <mass value="0.45"/>
      <inertia ixx="0.00092934" ixy="0.00000034" ixz="-0.00000738" iyy="0.00071447" iyz="0.00000005" izz="0.00039442"/>
    </inertial>
    <visual>
      <origin rpy="0 0 0" xyz="0 0 0"/>
      <geometry>
        <mesh filename="package://nero_description/meshes/dae/gripper_base.dae"/>
      </geometry>
    </visual>
    <collision>
      <origin rpy="0 0 0" xyz="0 0 0"/>
      <geometry>
        <mesh filename="package://nero_description/meshes/gripper_base.stl"/>
      </geometry>
    </collision>
  </link>
  <joint name="left_gripper_base_joint" type="fixed">
    <origin rpy="0 0 0" xyz="0 0 0.0055"/>
    <parent link="left_gripper_flange"/>
    <child link="left_gripper_base"/>
  </joint>
  <link name="left_gripper_link1">
    <inertial>
      <origin rpy="0 0 0" xyz="0.00065123185041968 -0.0491929869131989 0.00972258769184025"/>
      <mass value="0.025"/>
      <inertia ixx="0.00007371" ixy="-0.00000113" ixz="0.00000021" iyy="0.00000781" iyz="-0.00001372" izz="0.0000747"/>
    </inertial>
    <visual>
      <origin rpy="0 0 0" xyz="0 0 0"/>
      <geometry>
        <mesh filename="package://nero_description/meshes/dae/gripper_link1.dae"/>
      </geometry>
    </visual>
    <collision>
      <origin rpy="0 0 0" xyz="0 0 0"/>
      <geometry>
        <mesh filename="package://nero_description/meshes/gripper_link1.stl"/>
      </geometry>
    </collision>
  </link>
  <joint name="left_gripper_joint1" type="prismatic">
    <origin rpy="1.5707963 0 3.1415926" xyz="0 0 0.1358"/>
    <parent link="left_gripper_base"/>
    <child link="left_gripper_link1"/>
    <axis xyz="0 0 1"/>
    <limit effort="10" lower="0" upper="0.05" velocity="3"/>
  </joint>
  <link name="left_gripper_link2">
    <inertial>
      <origin rpy="0 0 0" xyz="0.00065123185041968 -0.0491929869131989 0.00972258769184025"/>
      <mass value="0.025"/>
      <inertia ixx="0.00007371" ixy="-0.00000113" ixz="0.00000021" iyy="0.00000781" iyz="-0.00001372" izz="0.0000747"/>
    </inertial>
    <visual>
      <origin rpy="0 0 0" xyz="0 0 0"/>
      <geometry>
        <mesh filename="package://nero_description/meshes/dae/gripper_link2.dae"/>
      </geometry>
    </visual>
    <collision>
      <origin rpy="0 0 0" xyz="0 0 0"/>
      <geometry>
        <mesh filename="package://nero_description/meshes/gripper_link2.stl"/>
      </geometry>
    </collision>
  </link>
  <joint name="left_gripper_joint2" type="prismatic">
    <origin rpy="1.5707963 0 0" xyz="0 0 0.1358"/>
    <parent link="left_gripper_base"/>
    <child link="left_gripper_link2"/>
    <axis xyz="0 0 -1"/>
    <limit effort="10" lower="-0.05" upper="0" velocity="3"/>
  </joint>
  <link name="right_gripper_flange">
    <inertial>
      <origin rpy="0 0 0" xyz="0.0 0.0 -0.00032"/>
      <mass value="0.04771096"/>
      <inertia ixx="2.697e-05" ixy="0" ixz="0" iyy="4.311e-05" iyz="0" izz="2.479e-05"/>
    </inertial>
    <visual>
      <origin rpy="0 0 0" xyz="0 0 0"/>
      <geometry>
        <mesh filename="package://nero_description/meshes/dae/gripper_flange.dae"/>
      </geometry>
    </visual>
    <collision>
      <origin rpy="0 0 0" xyz="0 0 0"/>
      <geometry>
        <mesh filename="package://nero_description/meshes/gripper_flange.stl"/>
      </geometry>
    </collision>
  </link>
  <joint name="right_gripper_flange_joint" type="fixed">
    <parent link="right_link7"/>
    <child link="right_gripper_flange"/>
    <origin rpy="-1.5708 0 -1.5708" xyz="0.032 0 -0.0235"/>
  </joint>
  <link name="right_gripper_base">
    <inertial>
      <origin rpy="0 0 0" xyz="-0.000183807162235591 8.05033155577911E-05 0.0321436689908876"/>
      <mass value="0.45"/>
      <inertia ixx="0.00092934" ixy="0.00000034" ixz="-0.00000738" iyy="0.00071447" iyz="0.00000005" izz="0.00039442"/>
    </inertial>
    <visual>
      <origin rpy="0 0 0" xyz="0 0 0"/>
      <geometry>
        <mesh filename="package://nero_description/meshes/dae/gripper_base.dae"/>
      </geometry>
    </visual>
    <collision>
      <origin rpy="0 0 0" xyz="0 0 0"/>
      <geometry>
        <mesh filename="package://nero_description/meshes/gripper_base.stl"/>
      </geometry>
    </collision>
  </link>
  <joint name="right_gripper_base_joint" type="fixed">
    <origin rpy="0 0 0" xyz="0 0 0.0055"/>
    <parent link="right_gripper_flange"/>
    <child link="right_gripper_base"/>
  </joint>
  <link name="right_gripper_link1">
    <inertial>
      <origin rpy="0 0 0" xyz="0.00065123185041968 -0.0491929869131989 0.00972258769184025"/>
      <mass value="0.025"/>
      <inertia ixx="0.00007371" ixy="-0.00000113" ixz="0.00000021" iyy="0.00000781" iyz="-0.00001372" izz="0.0000747"/>
    </inertial>
    <visual>
      <origin rpy="0 0 0" xyz="0 0 0"/>
      <geometry>
        <mesh filename="package://nero_description/meshes/dae/gripper_link1.dae"/>
      </geometry>
    </visual>
    <collision>
      <origin rpy="0 0 0" xyz="0 0 0"/>
      <geometry>
        <mesh filename="package://nero_description/meshes/gripper_link1.stl"/>
      </geometry>
    </collision>
  </link>
  <joint name="right_gripper_joint1" type="prismatic">
    <origin rpy="1.5707963 0 3.1415926" xyz="0 0 0.1358"/>
    <parent link="right_gripper_base"/>
    <child link="right_gripper_link1"/>
    <axis xyz="0 0 1"/>
    <limit effort="10" lower="0" upper="0.05" velocity="3"/>
  </joint>
  <link name="right_gripper_link2">
    <inertial>
      <origin rpy="0 0 0" xyz="0.00065123185041968 -0.0491929869131989 0.00972258769184025"/>
      <mass value="0.025"/>
      <inertia ixx="0.00007371" ixy="-0.00000113" ixz="0.00000021" iyy="0.00000781" iyz="-0.00001372" izz="0.0000747"/>
    </inertial>
    <visual>
      <origin rpy="0 0 0" xyz="0 0 0"/>
      <geometry>
        <mesh filename="package://nero_description/meshes/dae/gripper_link2.dae"/>
      </geometry>
    </visual>
    <collision>
      <origin rpy="0 0 0" xyz="0 0 0"/>
      <geometry>
        <mesh filename="package://nero_description/meshes/gripper_link2.stl"/>
      </geometry>
    </collision>
  </link>
  <joint name="right_gripper_joint2" type="prismatic">
    <origin rpy="1.5707963 0 0" xyz="0 0 0.1358"/>
    <parent link="right_gripper_base"/>
    <child link="right_gripper_link2"/>
    <axis xyz="0 0 -1"/>
    <limit effort="10" lower="-0.05" upper="0" velocity="3"/>
  </joint>
</robot>
